Traceback (most recent call last):
  File "/home/pi/sources/CSharp_review/serial_mqtt_test/mqtt/mqtt_test1.py", line 17, in <module>
    client.connect("192.168.124.102", 1883)
  File "/usr/local/lib/python3.9/dist-packages/paho/mqtt/client.py", line 914, in connect
    return self.reconnect()
  File "/usr/local/lib/python3.9/dist-packages/paho/mqtt/client.py", line 1044, in reconnect
    sock = self._create_socket_connection()
  File "/usr/local/lib/python3.9/dist-packages/paho/mqtt/client.py", line 3685, in _create_socket_connection
    return socket.create_connection(addr, timeout=self._connect_timeout, source_address=source)
  File "/usr/lib/python3.9/socket.py", line 843, in create_connection
    raise err
  File "/usr/lib/python3.9/socket.py", line 831, in create_connection
    sock.connect(sa)
socket.timeout: timed out